<mujoco model="DARU_stand">
  <compiler angle="radian"/>

  <asset>

    <model name="R_hand" file="/home/rclab/mujoco_models/Rough/rough_R.xml"/>  
    <model name="L_hand" file="/home/rclab/mujoco_models/Rough/rough_L.xml"/>  

    <mesh name="Base" content_type="model/stl" file="Base.STL"/>
    <mesh name="UB_Link" content_type="model/stl" file="UB_Link.STL"/>
    <mesh name="RSP_Link" content_type="model/stl" file="RSP_Link.STL"/>
    <mesh name="RSR_Link" content_type="model/stl" file="RSR_Link.STL"/>
    <mesh name="RSY_Link" content_type="model/stl" file="RSY_Link.STL"/>
    <mesh name="REP_Link" content_type="model/stl" file="REP_Link.STL"/>
    <mesh name="REY_Link" content_type="model/stl" file="REY_Link.STL"/>
    <mesh name="RWR_Link" content_type="model/stl" file="RWR_Link.STL"/>
    <mesh name="RWP_Link" content_type="model/stl" file="RWP_Link.STL"/>
    <mesh name="LSP_Link" content_type="model/stl" file="LSP_Link.STL"/>
    <mesh name="LSR_Link" content_type="model/stl" file="LSR_Link.STL"/>
    <mesh name="LSY_Link" content_type="model/stl" file="LSY_Link.STL"/>
    <mesh name="LEP_Link" content_type="model/stl" file="LEP_Link.STL"/>
    <mesh name="LEY_Link" content_type="model/stl" file="LEY_Link.STL"/>
    <mesh name="LWR_Link" content_type="model/stl" file="LWR_Link.STL"/>
    <mesh name="LWP_Link" content_type="model/stl" file="LWP_Link.STL"/>
    <mesh name="HY_Link" content_type="model/stl" file="HY_Link.STL"/>
    <mesh name="HP_Link" content_type="model/stl" file="HP_Link.STL"/>
  
    <material name="metal_silver"
            specular="0.5"    
            shininess="1.0"   
            reflectance="0.3" 
            rgba="0.2 0.2 0.2 1"/> 
  
  </asset>

  <contact>
    <!-- <exclude body1="Base" body2="UB_Link"/> -->

    <exclude body1="UB_Link" body2="RSP_Link"/>
    <exclude body1="RSP_Link" body2="RSR_Link"/>
    <exclude body1="RSR_Link" body2="RSY_Link"/>
    <exclude body1="RSY_Link" body2="REP_Link"/>
    <exclude body1="REP_Link" body2="REY_Link"/>
    <exclude body1="REY_Link" body2="RWR_Link"/>
    <exclude body1="RWR_Link" body2="RWP_Link"/>
    
    <exclude body1="UB_Link" body2="LSP_Link"/>
    <exclude body1="LSP_Link" body2="LSR_Link"/>
    <exclude body1="LSR_Link" body2="LSY_Link"/>
    <exclude body1="LSY_Link" body2="LEP_Link"/>
    <exclude body1="LEP_Link" body2="LEY_Link"/>
    <exclude body1="LEY_Link" body2="LWR_Link"/>
    <exclude body1="LWR_Link" body2="LWP_Link"/>

    <exclude body1="HY_Link" body2="HP_Link"/>
    <exclude body1="UB_Link" body2="HP_Link"/>
  </contact>

  <default>
    <default class="X12_150">
      <motor gear="1" ctrlrange="-150 150"/>
    </default>

    <default class="X6_60">
      <motor gear="1" ctrlrange="-60 60"/>
    </default>

    <default class="X4_10">
      <motor gear="1" ctrlrange="-10 10"/>
    </default>

    <default class="X2_07">
      <motor gear="1" ctrlrange="-7 7"/> 
    </default>
  </default>

  <actuator>
    <!-- 허리 -->
    <motor name="WY" class="X12_150" joint="Waist_Joint"/>

    <!-- 오른팔 -->
    <motor name="RSP" class="X6_60" joint="RSP_Joint"/>
    <motor name="RSR" class="X6_60" joint="RSR_Joint"/>
    <motor name="RSY" class="X6_60" joint="RSY_Joint"/>
    <motor name="REP" class="X6_60" joint="REP_Joint"/>
    <motor name="REY" class="X4_10" joint="REY_Joint"/>
    <motor name="RWR" class="X4_10" joint="RWR_Joint"/>
    <motor name="RWP" class="X4_10" joint="RWP_Joint"/>
    <!-- 왼팔 -->
    <motor name="LSP" class="X6_60" joint="LSP_Joint"/>
    <motor name="LSR" class="X6_60" joint="LSR_Joint"/>
    <motor name="LSY" class="X6_60" joint="LSY_Joint"/>
    <motor name="LEP" class="X6_60" joint="LEP_Joint"/>
    <motor name="LEY" class="X4_10" joint="LEY_Joint"/>
    <motor name="LWR" class="X4_10" joint="LWR_Joint"/>
    <motor name="LWP" class="X4_10" joint="LWP_Joint"/>
    <!-- 머리 -->
    <motor name="HY" class="X2_07" joint="HY_Joint"/>
    <motor name="HP" class="X2_07" joint="HP_Joint"/>
  </actuator>

  <worldbody>
    <body name="Base" pos="0 0 0.75">
      <joint name="root_free" type="free"/>
      <inertial pos="0 0 0" quat="1 0 0 0" mass="5.0" diaginertia="0.1 0.1 0.1"/>
      <geom type="mesh" mesh="Base" contype="0" conaffinity="0" material="metal_silver"/>
      <body name="UB_Link">
        <inertial pos="-0.0507646 2.076e-05 0.269453" quat="0.999045 0.000129377 0.0436833 -0.000203278" mass="14.7807" diaginertia="0.274438 0.254941 0.146742"/>
        <joint name="Waist_Joint" pos="0 0 0" axis="0 0 1" range="-1.5708 1.5708" damping="0.0" frictionloss="0.0"/>
        <geom type="mesh" mesh="UB_Link" material="metal_silver"/>
        <body name="RSP_Link" pos="0 -0.225 0.3925">
          <inertial pos="0.00033313 0.00631764 0.00011791" quat="0.469401 0.470201 -0.526788 0.530159" mass="1.09643" diaginertia="0.00148436 0.00143505 0.00116252"/>
          <joint name="RSP_Joint" pos="0 0 0" axis="0 1 0" range="-4.460 0.837" damping="0.01" frictionloss="1.0"/>
          <geom type="mesh" mesh="RSP_Link" material="metal_silver"/>
          <body name="RSR_Link">
            <inertial pos="-0.00773789 -0.00013658 -0.0808405" quat="0.692031 -0.170654 -0.177473 0.678582" mass="1.1089" diaginertia="0.00200261 0.00190758 0.001159"/>
            <joint name="RSR_Joint" pos="0 0 0" axis="1 0 0" range="-3.491 0.349" damping="0.01" frictionloss="1.0"/>
            <geom type="mesh" mesh="RSR_Link" material="metal_silver"/>
            <body name="RSY_Link">
              <inertial pos="-0.00104042 -0.00328212 -0.191833" quat="0.998994 0.0254289 0.0349831 0.0118134" mass="1.31388" diaginertia="0.00303097 0.00294897 0.00136975"/>
              <joint name="RSY_Joint" pos="0 0 0" axis="0 0 1" range="-2.87979 2.87979" damping="0.01" frictionloss="1.0"/>
              <geom type="mesh" mesh="RSY_Link" material="metal_silver"/>
              <body name="REP_Link" pos="0 0 -0.3">
                <inertial pos="-0.0013698 -3.287e-05 -0.0692101" quat="0.726958 -0.0147117 -0.0142461 0.686377" mass="0.442059" diaginertia="0.00080198 0.000775082 0.000248848"/>
                <joint name="REP_Joint" pos="0 0 0" axis="0 1 0" range="-2.35619 0" damping="0.01" frictionloss="1.0"/>
                <geom type="mesh" mesh="REP_Link" material="metal_silver"/>
                <body name="REY_Link">
                  <inertial pos="0.00267605 -5.449e-05 -0.144684" quat="0.661611 0.191342 0.155231 0.708211" mass="0.306356" diaginertia="0.000192415 0.000178187 0.000163848"/>
                  <joint name="REY_Joint" pos="0 0 0" axis="0 0 1" range="-1.5708 1.5708" damping="0.01" frictionloss="1.0"/>
                  <geom type="mesh" mesh="REY_Link" material="metal_silver"/>
                  <body name="RWR_Link" pos="0 0 -0.148">
                    <inertial pos="0.00297563 -0.0284565 -0.0553425" quat="0.917533 -0.288581 0.219655 0.163111" mass="0.329053" diaginertia="0.000333126 0.000317397 0.000167577"/>
                    <joint name="RWR_Joint" pos="0 0 0" axis="1 0 0" range="-1.5708 1.5708" damping="0.01" frictionloss="1.0"/>
                    <geom type="mesh" mesh="RWR_Link" material="metal_silver"/>
                    <body name="RWP_Link" pos="0 0 -0.0625">
                      <inertial pos="0.0431291 -0.00434224 -0.0143786" quat="-0.166252 0.740498 -0.250776 0.600945" mass="0.108733" diaginertia="0.000178378 0.000173519 2.43732e-05"/>
                      <joint name="RWP_Joint" pos="0 0 0" axis="0 1 0" range="-1.5708 1.5708" damping="0.01" frictionloss="1.0"/>
                      <geom type="mesh" mesh="RWP_Link" material="metal_silver"/>
                      <body name="R_hand" pos="0 -0.002 -0.0253" euler="3.141592 0 -1.5708">
                        <attach model="R_hand"  prefix="RHand_"/>
                      </body>
                    </body>
                  </body>
                </body>
              </body>
            </body>
          </body>
        </body>
        <body name="LSP_Link" pos="0 0.225 0.3925">
          <inertial pos="0.00023229 -0.00621771 -0.00015876" quat="0.524908 0.534257 -0.466047 0.471" mass="1.09329" diaginertia="0.00146957 0.00142974 0.00115004"/>
          <joint name="LSP_Joint" pos="0 0 0" axis="0 1 0" range="-4.460 0.8378" damping="0.01" frictionloss="1.0"/>
          <geom type="mesh"  mesh="LSP_Link" material="metal_silver"/>
          <body name="LSR_Link">
            <inertial pos="-0.00773794 -0.00013656 -0.0808405" quat="0.692032 -0.170655 -0.177474 0.678581" mass="1.1089" diaginertia="0.00200261 0.0019076 0.00115899"/>
            <joint name="LSR_Joint" pos="0 0 0" axis="1 0 0" range="-0.349 3.491" damping="0.01" frictionloss="1.0"/>
            <geom type="mesh"  mesh="LSR_Link" material="metal_silver"/>
            <body name="LSY_Link">
              <inertial pos="-0.00129204 0.00333021 -0.19157" quat="0.99714 -0.0219468 0.0377979 0.061652" mass="1.30782" diaginertia="0.00300549 0.0029214 0.00136631"/>
              <joint name="LSY_Joint" pos="0 0 0" axis="0 0 1" range="-2.87979 2.87979" damping="0.01" frictionloss="1.0"/>
              <geom type="mesh"  mesh="LSY_Link" material="metal_silver"/>
              <body name="LEP_Link" pos="0 0 -0.3">
                <inertial pos="-0.00136083 3.812e-05 -0.06921" quat="0.690403 -0.0141392 -0.0146771 0.723138" mass="0.442059" diaginertia="0.000802411 0.000774652 0.000248867"/>
                <joint name="LEP_Joint" pos="0 0 0" axis="0 1 0" range="-2.35619 0" damping="0.01" frictionloss="1.0"/>
                <geom type="mesh"  mesh="LEP_Link" material="metal_silver"/>
                <body name="LEY_Link">
                  <inertial pos="0.00267605 -0.00012191 -0.144582" quat="0.670867 0.136457 0.134863 0.71633" mass="0.306356" diaginertia="0.000195047 0.000176732 0.000162241"/>
                  <joint name="LEY_Joint" pos="0 0 0" axis="0 0 1" range="-1.5708 1.5708" damping="0.01" frictionloss="1.0"/>
                  <geom type="mesh"  mesh="LEY_Link" material="metal_silver"/>
                  <body name="LWR_Link" pos="0 0 -0.148">
                    <inertial pos="0.0029249 0.0293125 -0.0554304" quat="0.903175 0.281632 0.242805 -0.214485" mass="0.329053" diaginertia="0.000336821 0.000321128 0.000167"/>
                    <joint name="LWR_Joint" pos="0 0 0" axis="1 0 0" range="-1.5708 1.5708" damping="0.01" frictionloss="1.0"/>
                    <geom type="mesh"  mesh="LWR_Link" material="metal_silver"/>
                    <body name="LWP_Link" pos="0 0 -0.0625">
                      <inertial pos="0.0431343 0.00528524 -0.0143643" quat="0.16844 0.739926 0.252005 0.600526" mass="0.108733" diaginertia="0.000178364 0.000173494 2.43421e-05"/>
                      <joint name="LWP_Joint" pos="0 0 0" axis="0 1 0" range="-1.5708 1.5708" damping="0.01" frictionloss="1.0"/>
                      <geom type="mesh"  mesh="LWP_Link" material="metal_silver"/>
                      <body name="L_hand" pos="0 0.002 -0.0253" euler="3.141592 0 1.5708">
                        <attach model="L_hand"  prefix="LHand_"/>
                      </body>
                    </body>
                  </body>
                </body>
              </body>
            </body>
          </body>
        </body>
        <body name="HY_Link" pos="0 0 0.5855">
          <inertial pos="-0.00136668 -0.00281064 -0.0163791" quat="0.709902 0.686287 0.119444 -0.103836" mass="0.0824974" diaginertia="6.43821e-05 5.72521e-05 4.95557e-05"/>
          <joint name="HY_Joint" pos="0 0 0" axis="0 0 1" range="-1.5708 1.5708" damping="0.01" frictionloss="1.0"/>
          <geom type="mesh" mesh="HY_Link" material="metal_silver"/>
          <body name="HP_Link">
            <inertial pos="0.0113946 -0.00069587 0.032575" quat="0.935722 0.00167622 -0.35249 -0.0131194" mass="0.94946" diaginertia="0.00662813 0.00602591 0.00512292"/>
            <joint name="HP_Joint" pos="0 0 0" axis="0 1 0" range="-0.785398 0.3316" damping="0.01" frictionloss="1.0"/>
            <geom type="mesh" mesh="HP_Link" material="metal_silver"/>
            <camera name="front_cam"
              pos="0.08 0 -0.08"
              euler="0 -1.0708 -1.5708"
              fovy="58"/>
          </body>
        </body>
      </body>
    </body>
  </worldbody>
</mujoco>
