<mujoco model="L_hand">
  <compiler angle="radian"/>

  <default>
    <default class="P1_main">
      <default class="P1_T1_main"/>
      <default class="P1_F1_main"/>
      <default class="P1_F2_main"/>
      <default class="P1_F3_main"/>
      <default class="P1_F4_main"/>
    </default>
  </default>

  <asset>
    <material name="P1_metal_silver" specular="0" shininess="1" reflectance="0.3" rgba="0.2 0.2 0.2 1"/>
    <material name="P1_metal_white" specular="0" shininess="1" reflectance="0.3" rgba="0.9 0.9 0.9 1"/>
    <material name="P1_T1_metal_silver" specular="0" shininess="1" reflectance="0.3" rgba="0.2 0.2 0.2 1"/>
    <material name="P1_T1_metal_white" specular="0" shininess="1" reflectance="0.3" rgba="0.9 0.9 0.9 1"/>
    <material name="P1_F1_metal_silver" specular="0" shininess="1" reflectance="0.3" rgba="0.2 0.2 0.2 1"/>
    <material name="P1_F1_metal_white" specular="0" shininess="1" reflectance="0.3" rgba="0.9 0.9 0.9 1"/>
    <material name="P1_F2_metal_silver" specular="0" shininess="1" reflectance="0.3" rgba="0.2 0.2 0.2 1"/>
    <material name="P1_F2_metal_white" specular="0" shininess="1" reflectance="0.3" rgba="0.9 0.9 0.9 1"/>
    <material name="P1_F3_metal_silver" specular="0" shininess="1" reflectance="0.3" rgba="0.2 0.2 0.2 1"/>
    <material name="P1_F3_metal_white" specular="0" shininess="1" reflectance="0.3" rgba="0.9 0.9 0.9 1"/>
    <material name="P1_F4_metal_silver" specular="0" shininess="1" reflectance="0.3" rgba="0.2 0.2 0.2 1"/>
    <material name="P1_F4_metal_white" specular="0" shininess="1" reflectance="0.3" rgba="0.9 0.9 0.9 1"/>
    <mesh name="P1_Base" content_type="model/stl" file="palm_simple_l/meshes/Base.STL"/>
    <mesh name="P1_Link_1" content_type="model/stl" file="palm_simple_l/meshes/Link_1.STL"/>
    <mesh name="P1_T1_Base_Link" content_type="model/stl" file="thumb_simple_l/meshes/Base_Link.STL"/>
    <mesh name="P1_T1_Link_1" content_type="model/stl" file="thumb_simple_l/meshes/Link_1.STL"/>
    <mesh name="P1_T1_Link_2" content_type="model/stl" file="thumb_simple_l/meshes/Link_2.STL"/>
    <mesh name="P1_F1_Base_Link" content_type="model/stl" file="finger_simple_l/meshes/Base_Link.STL"/>
    <mesh name="P1_F1_Link_1" content_type="model/stl" file="finger_simple_l/meshes/Link_1.STL"/>
    <mesh name="P1_F1_Link_2" content_type="model/stl" file="finger_simple_l/meshes/Link_2.STL"/>
    <mesh name="P1_F1_Link_3" content_type="model/stl" file="finger_simple_l/meshes/Link_3.STL"/>
    <mesh name="P1_F2_Base_Link" content_type="model/stl" file="finger_simple_l/meshes/Base_Link.STL"/>
    <mesh name="P1_F2_Link_1" content_type="model/stl" file="finger_simple_l/meshes/Link_1.STL"/>
    <mesh name="P1_F2_Link_2" content_type="model/stl" file="finger_simple_l/meshes/Link_2.STL"/>
    <mesh name="P1_F2_Link_3" content_type="model/stl" file="finger_simple_l/meshes/Link_3.STL"/>
    <mesh name="P1_F3_Base_Link" content_type="model/stl" file="finger_simple_l/meshes/Base_Link.STL"/>
    <mesh name="P1_F3_Link_1" content_type="model/stl" file="finger_simple_l/meshes/Link_1.STL"/>
    <mesh name="P1_F3_Link_2" content_type="model/stl" file="finger_simple_l/meshes/Link_2.STL"/>
    <mesh name="P1_F3_Link_3" content_type="model/stl" file="finger_simple_l/meshes/Link_3.STL"/>
    <mesh name="P1_F4_Base_Link" content_type="model/stl" file="finger_simple_l/meshes/Base_Link.STL"/>
    <mesh name="P1_F4_Link_1" content_type="model/stl" file="finger_simple_l/meshes/Link_1.STL"/>
    <mesh name="P1_F4_Link_2" content_type="model/stl" file="finger_simple_l/meshes/Link_2.STL"/>
    <mesh name="P1_F4_Link_3" content_type="model/stl" file="finger_simple_l/meshes/Link_3.STL"/>
  </asset>

  <worldbody>
    <body name="L_hand">
      <body name="P1_Base">
        <inertial pos="-0.00225524 0.00380216 0.0473862" mass="0.171128" diaginertia="0.00021357 0.00015811 0.00013249"/>
        <geom type="mesh" material="P1_metal_silver" mesh="P1_Base"/>
        <body name="P1_Link_1" pos="0.018 -0.0225 0.034">
          <inertial pos="0.0134559 -0.00740936 -0.00938192" quat="0.635518 -0.0651905 -0.41216 -0.649608" mass="0.00822579" diaginertia="1.61083e-06 1.28505e-06 4.24121e-07"/>
          <joint name="P1_Joint_1" pos="0 0 0" axis="0 0 1" range="0 1.57" damping="0.2" frictionloss="2"/>
          <geom type="mesh" material="P1_metal_silver" mesh="P1_Link_1"/>
          <body name="P1_thumb" pos="0.0170702 -0.0520505 0.0213876" quat="0.656402 0.261099 -0.262475 0.657321">
            <body name="P1_T1_Base">
              <inertial pos="-0.00475219 -0.00062534 -0.0379381" quat="0.999751 0 0.0223266 0" mass="0.0653603" diaginertia="3.426e-05 3.493e-05 3.81e-06"/>
              <geom type="mesh" material="P1_T1_metal_silver" mesh="P1_T1_Base_Link"/>
              <body name="P1_T1_Link_1">
                <inertial pos="-0.00287404 0 0.0162789" quat="0.999751 0 0.0223266 0" mass="0.00740117" diaginertia="1.03134e-06 9.9e-07 3.58659e-07"/>
                <joint name="P1_T1_Joint_1" pos="0 0 0" axis="0 1 0" range="0 1.57" damping="0.05"/>
                <geom type="mesh" material="P1_T1_metal_silver" mesh="P1_T1_Link_1"/>
                <body name="P1_T1_Link_2" pos="-0.00411843 0 0.0300462">
                  <inertial pos="0.00350288 0 0.0168479" quat="0.704715 -0.0581027 0.0581027 -0.704716" mass="0.00721927" diaginertia="7.3e-07 6.91622e-07 2.58378e-07"/>
                  <joint name="P1_T1_Joint_2" pos="0 0 0" axis="0 1 0" range="0 1.57" damping="0.01"/>
                  <geom type="mesh" material="P1_T1_metal_white" mesh="P1_T1_Link_2"/>
                </body>
              </body>
            </body>
          </body>
        </body>
        <body name="P1_finger1" pos="-0.007 0.0394653 0.0994938" quat="0.99863 -0.0523361 0 0">
          <body name="P1_F1_Base">
            <inertial pos="-0.00704727 -4.379e-05 -0.0572773" mass="0.0652522" diaginertia="5.262e-05 5.34e-05 2.29e-06"/>
            <geom type="mesh" material="P1_F1_metal_silver" mesh="P1_F1_Base_Link"/>
            <body name="P1_F1_Link_1">
              <inertial pos="-0.0026752 0 0.0159413" quat="0.706504 0.0291861 -0.0291861 -0.706504" mass="0.00740117" diaginertia="1.01e-06 1.00414e-06 3.95862e-07"/>
              <joint name="P1_F1_Joint_1" pos="0 0 0" axis="0 1 0" range="0 1.57" damping="0.05"/>
              <geom type="mesh" material="P1_F1_metal_silver" mesh="P1_F1_Link_1"/>
              <body name="P1_F1_Link_2" pos="-0.002 0 0.0270208">
                <inertial pos="0.00120264 0 0.0145486" mass="0.0063781" diaginertia="6e-07 5.5e-07 3.1e-07"/>
                <joint name="P1_F1_Joint_2" pos="0 0 0" axis="0 1 0" range="0 1.57" damping="0.01"/>
                <geom type="mesh" material="P1_F1_metal_silver" mesh="P1_F1_Link_2"/>
                <body name="P1_F1_Link_3" pos="0 0 0.0233281">
                  <inertial pos="0.00074576 0 0.017192" quat="0.707107 0 0 -0.707107" mass="0.00721927" diaginertia="7.3e-07 6.9e-07 2.6e-07"/>
                  <joint name="P1_F1_Joint_3" pos="0 0 0" axis="0 1 0" range="0 1.57" damping="0.001"/>
                  <geom type="mesh" material="P1_F1_metal_white" mesh="P1_F1_Link_3"/>
                </body>
              </body>
            </body>
          </body>
        </body>
        <body name="P1_finger2" pos="-0.007 0.0161445 0.10625" quat="0.999657 -0.026177 0 0">
          <body name="P1_F2_Base">
            <inertial pos="-0.00704727 -4.379e-05 -0.0572773" mass="0.0652522" diaginertia="5.262e-05 5.34e-05 2.29e-06"/>
            <geom type="mesh" material="P1_F2_metal_silver" mesh="P1_F2_Base_Link"/>
            <body name="P1_F2_Link_1">
              <inertial pos="-0.0026752 0 0.0159413" quat="0.706504 0.0291861 -0.0291861 -0.706504" mass="0.00740117" diaginertia="1.01e-06 1.00414e-06 3.95862e-07"/>
              <joint name="P1_F2_Joint_1" pos="0 0 0" axis="0 1 0" range="0 1.57" damping="0.05"/>
              <geom type="mesh" material="P1_F2_metal_silver" mesh="P1_F2_Link_1"/>
              <body name="P1_F2_Link_2" pos="-0.002 0 0.0270208">
                <inertial pos="0.00120264 0 0.0145486" mass="0.0063781" diaginertia="6e-07 5.5e-07 3.1e-07"/>
                <joint name="P1_F2_Joint_2" pos="0 0 0" axis="0 1 0" range="0 1.57" damping="0.01"/>
                <geom type="mesh" material="P1_F2_metal_silver" mesh="P1_F2_Link_2"/>
                <body name="P1_F2_Link_3" pos="0 0 0.0233281">
                  <inertial pos="0.00074576 0 0.017192" quat="0.707107 0 0 -0.707107" mass="0.00721927" diaginertia="7.3e-07 6.9e-07 2.6e-07"/>
                  <joint name="P1_F2_Joint_3" pos="0 0 0" axis="0 1 0" range="0 1.57" damping="0.001"/>
                  <geom type="mesh" material="P1_F2_metal_white" mesh="P1_F2_Link_3"/>
                </body>
              </body>
            </body>
          </body>
        </body>
        <body name="P1_finger3" pos="-0.007 -0.0075 0.1097">
          <body name="P1_F3_Base">
            <inertial pos="-0.00704727 -4.379e-05 -0.0572773" mass="0.0652522" diaginertia="5.262e-05 5.34e-05 2.29e-06"/>
            <geom type="mesh" material="P1_F3_metal_silver" mesh="P1_F3_Base_Link"/>
            <body name="P1_F3_Link_1">
              <inertial pos="-0.0026752 0 0.0159413" quat="0.706504 0.0291861 -0.0291861 -0.706504" mass="0.00740117" diaginertia="1.01e-06 1.00414e-06 3.95862e-07"/>
              <joint name="P1_F3_Joint_1" pos="0 0 0" axis="0 1 0" range="0 1.57" damping="0.05"/>
              <geom type="mesh" material="P1_F3_metal_silver" mesh="P1_F3_Link_1"/>
              <body name="P1_F3_Link_2" pos="-0.002 0 0.0270208">
                <inertial pos="0.00120264 0 0.0145486" mass="0.0063781" diaginertia="6e-07 5.5e-07 3.1e-07"/>
                <joint name="P1_F3_Joint_2" pos="0 0 0" axis="0 1 0" range="0 1.57" damping="0.01"/>
                <geom type="mesh" material="P1_F3_metal_silver" mesh="P1_F3_Link_2"/>
                <body name="P1_F3_Link_3" pos="0 0 0.0233281">
                  <inertial pos="0.00074576 0 0.017192" quat="0.707107 0 0 -0.707107" mass="0.00721927" diaginertia="7.3e-07 6.9e-07 2.6e-07"/>
                  <joint name="P1_F3_Joint_3" pos="0 0 0" axis="0 1 0" range="0 1.57" damping="0.001"/>
                  <geom type="mesh" material="P1_F3_metal_white" mesh="P1_F3_Link_3"/>
                </body>
              </body>
            </body>
          </body>
        </body>
        <body name="P1_finger4" pos="-0.007 -0.0311425 0.109212" quat="0.999657 0.026177 0 0">
          <body name="P1_F4_Base">
            <inertial pos="-0.00704727 -4.379e-05 -0.0572773" mass="0.0652522" diaginertia="5.262e-05 5.34e-05 2.29e-06"/>
            <geom type="mesh" material="P1_F4_metal_silver" mesh="P1_F4_Base_Link"/>
            <body name="P1_F4_Link_1">
              <inertial pos="-0.0026752 0 0.0159413" quat="0.706504 0.0291861 -0.0291861 -0.706504" mass="0.00740117" diaginertia="1.01e-06 1.00414e-06 3.95862e-07"/>
              <joint name="P1_F4_Joint_1" pos="0 0 0" axis="0 1 0" range="0 1.57" damping="0.05"/>
              <geom type="mesh" material="P1_F4_metal_silver" mesh="P1_F4_Link_1"/>
              <body name="P1_F4_Link_2" pos="-0.002 0 0.0270208">
                <inertial pos="0.00120264 0 0.0145486" mass="0.0063781" diaginertia="6e-07 5.5e-07 3.1e-07"/>
                <joint name="P1_F4_Joint_2" pos="0 0 0" axis="0 1 0" range="0 1.57" damping="0.01"/>
                <geom type="mesh" material="P1_F4_metal_silver" mesh="P1_F4_Link_2"/>
                <body name="P1_F4_Link_3" pos="0 0 0.0233281">
                  <inertial pos="0.00074576 0 0.017192" quat="0.707107 0 0 -0.707107" mass="0.00721927" diaginertia="7.3e-07 6.9e-07 2.6e-07"/>
                  <joint name="P1_F4_Joint_3" pos="0 0 0" axis="0 1 0" range="0 1.57" damping="0.001"/>
                  <geom type="mesh" material="P1_F4_metal_white" mesh="P1_F4_Link_3"/>
                </body>
              </body>
            </body>
          </body>
        </body>
      </body>
    </body>
  </worldbody>

  <contact>
    <exclude body1="P1_Base" body2="P1_Link_1"/>
  </contact>

  <equality>
    <joint joint1="P1_T1_Joint_1" joint2="P1_T1_Joint_2" polycoef="0 1 0 0 0" solref="0.001" solimp="0.99 0.99"/>
    <joint joint1="P1_F1_Joint_1" joint2="P1_F1_Joint_2" polycoef="0 1 0 0 0" solref="0.001" solimp="0.99 0.99"/>
    <joint joint1="P1_F1_Joint_1" joint2="P1_F1_Joint_3" polycoef="0 1 0 0 0" solref="0.001" solimp="0.99 0.99"/>
    <joint joint1="P1_F2_Joint_1" joint2="P1_F2_Joint_2" polycoef="0 1 0 0 0" solref="0.001" solimp="0.99 0.99"/>
    <joint joint1="P1_F2_Joint_1" joint2="P1_F2_Joint_3" polycoef="0 1 0 0 0" solref="0.001" solimp="0.99 0.99"/>
    <joint joint1="P1_F3_Joint_1" joint2="P1_F3_Joint_2" polycoef="0 1 0 0 0" solref="0.001" solimp="0.99 0.99"/>
    <joint joint1="P1_F3_Joint_1" joint2="P1_F3_Joint_3" polycoef="0 1 0 0 0" solref="0.001" solimp="0.99 0.99"/>
    <joint joint1="P1_F4_Joint_1" joint2="P1_F4_Joint_2" polycoef="0 1 0 0 0" solref="0.001" solimp="0.99 0.99"/>
    <joint joint1="P1_F4_Joint_1" joint2="P1_F4_Joint_3" polycoef="0 1 0 0 0" solref="0.001" solimp="0.99 0.99"/>
  </equality>

  <actuator>
    <general name="P1_LM" joint="P1_Joint_1" ctrlrange="0 1.57" biastype="affine" biasprm="0 -1"/>
    <general name="T1_LM" joint="P1_T1_Joint_1" ctrlrange="0 1.57" biastype="affine" biasprm="0 -1"/>
    <general name="F1_LM" joint="P1_F1_Joint_1" ctrlrange="0 1.57" biastype="affine" biasprm="0 -1"/>
    <general name="F2_LM" joint="P1_F2_Joint_1" ctrlrange="0 1.57" biastype="affine" biasprm="0 -1"/>
    <general name="F3_LM" joint="P1_F3_Joint_1" ctrlrange="0 1.57" biastype="affine" biasprm="0 -1"/>
    <general name="F4_LM" joint="P1_F4_Joint_1" ctrlrange="0 1.57" biastype="affine" biasprm="0 -1"/>
  </actuator>
</mujoco>
